2024-07-18 15:17:42,049 INFO    MainThread:9420 [wandb_setup.py:_flush():76] Current SDK version is 0.17.4
2024-07-18 15:17:42,049 INFO    MainThread:9420 [wandb_setup.py:_flush():76] Configure stats pid to 9420
2024-07-18 15:17:42,049 INFO    MainThread:9420 [wandb_setup.py:_flush():76] Loading settings from C:\Users\grego\.config\wandb\settings
2024-07-18 15:17:42,049 INFO    MainThread:9420 [wandb_setup.py:_flush():76] Loading settings from E:\psychic-chainsaw\wandb\settings
2024-07-18 15:17:42,049 INFO    MainThread:9420 [wandb_setup.py:_flush():76] Loading settings from environment variables: {}
2024-07-18 15:17:42,049 INFO    MainThread:9420 [wandb_setup.py:_flush():76] Inferring run settings from compute environment: {'program_relpath': 'vit_model\\vit_model_chest_xray.py', 'program_abspath': 'e:\\psychic-chainsaw\\vit_model\\vit_model_chest_xray.py', 'program': 'e:\\psychic-chainsaw\\vit_model\\vit_model_chest_xray.py'}
2024-07-18 15:17:42,050 INFO    MainThread:9420 [wandb_setup.py:_flush():76] Applying login settings: {'api_key': '***REDACTED***'}
2024-07-18 15:17:42,050 INFO    MainThread:9420 [wandb_setup.py:_flush():76] Applying login settings: {'api_key': '***REDACTED***'}
2024-07-18 15:17:42,050 INFO    MainThread:9420 [wandb_setup.py:_flush():76] Applying login settings: {}
2024-07-18 15:17:42,050 INFO    MainThread:9420 [wandb_init.py:_log_setup():529] Logging user logs to E:\psychic-chainsaw\wandb\run-20240718_151742-rt9bn95e\logs\debug.log
2024-07-18 15:17:42,050 INFO    MainThread:9420 [wandb_init.py:_log_setup():530] Logging internal logs to E:\psychic-chainsaw\wandb\run-20240718_151742-rt9bn95e\logs\debug-internal.log
2024-07-18 15:17:42,050 INFO    MainThread:9420 [wandb_init.py:init():569] calling init triggers
2024-07-18 15:17:42,050 INFO    MainThread:9420 [wandb_init.py:init():576] wandb.init called with sweep_config: {}
config: {'learning_rate': 0.0003, 'batch_size': 32, 'num_epochs': 50, 'optimizer': 'Adam', 'loss_function': 'CrossEntropyLoss', 'model': 'Vision Transformer', 'dataset': 'Chest X-ray Pneumonia'}
2024-07-18 15:17:42,050 INFO    MainThread:9420 [wandb_init.py:init():619] starting backend
2024-07-18 15:17:42,050 INFO    MainThread:9420 [wandb_init.py:init():623] setting up manager
2024-07-18 15:17:42,051 INFO    MainThread:9420 [backend.py:_multiprocessing_setup():105] multiprocessing start_methods=spawn, using: spawn
2024-07-18 15:17:42,054 INFO    MainThread:9420 [wandb_init.py:init():631] backend started and connected
2024-07-18 15:17:42,056 INFO    MainThread:9420 [wandb_init.py:init():720] updated telemetry
2024-07-18 15:17:42,093 INFO    MainThread:9420 [wandb_init.py:init():753] communicating run to backend with 90.0 second timeout
2024-07-18 15:18:35,139 INFO    Thread-9 (wrapped_target):9420 [retry.py:__call__():172] Retry attempt failed:
Traceback (most recent call last):
  File "C:\Users\grego\AppData\Local\Programs\Python\Python311\Lib\site-packages\urllib3\connection.py", line 196, in _new_conn
    sock = connection.create_connection(
           ^^^^^^^^^^^^^^^^^^^^^^^^^^^^^
  File "C:\Users\grego\AppData\Local\Programs\Python\Python311\Lib\site-packages\urllib3\util\connection.py", line 85, in create_connection
    raise err
  File "C:\Users\grego\AppData\Local\Programs\Python\Python311\Lib\site-packages\urllib3\util\connection.py", line 73, in create_connection
    sock.connect(sa)
TimeoutError: timed out

The above exception was the direct cause of the following exception:

Traceback (most recent call last):
  File "C:\Users\grego\AppData\Local\Programs\Python\Python311\Lib\site-packages\urllib3\connectionpool.py", line 789, in urlopen
    response = self._make_request(
               ^^^^^^^^^^^^^^^^^^^
  File "C:\Users\grego\AppData\Local\Programs\Python\Python311\Lib\site-packages\urllib3\connectionpool.py", line 490, in _make_request
    raise new_e
  File "C:\Users\grego\AppData\Local\Programs\Python\Python311\Lib\site-packages\urllib3\connectionpool.py", line 466, in _make_request
    self._validate_conn(conn)
  File "C:\Users\grego\AppData\Local\Programs\Python\Python311\Lib\site-packages\urllib3\connectionpool.py", line 1095, in _validate_conn
    conn.connect()
  File "C:\Users\grego\AppData\Local\Programs\Python\Python311\Lib\site-packages\urllib3\connection.py", line 615, in connect
    self.sock = sock = self._new_conn()
                       ^^^^^^^^^^^^^^^^
  File "C:\Users\grego\AppData\Local\Programs\Python\Python311\Lib\site-packages\urllib3\connection.py", line 205, in _new_conn
    raise ConnectTimeoutError(
urllib3.exceptions.ConnectTimeoutError: (<urllib3.connection.HTTPSConnection object at 0x00000264EFE0DA50>, 'Connection to api.wandb.ai timed out. (connect timeout=20)')

The above exception was the direct cause of the following exception:

Traceback (most recent call last):
  File "C:\Users\grego\AppData\Local\Programs\Python\Python311\Lib\site-packages\requests\adapters.py", line 667, in send
    resp = conn.urlopen(
           ^^^^^^^^^^^^^
  File "C:\Users\grego\AppData\Local\Programs\Python\Python311\Lib\site-packages\urllib3\connectionpool.py", line 843, in urlopen
    retries = retries.increment(
              ^^^^^^^^^^^^^^^^^^
  File "C:\Users\grego\AppData\Local\Programs\Python\Python311\Lib\site-packages\urllib3\util\retry.py", line 519, in increment
    raise MaxRetryError(_pool, url, reason) from reason  # type: ignore[arg-type]
    ^^^^^^^^^^^^^^^^^^^^^^^^^^^^^^^^^^^^^^^^^^^^^^^^^^^
urllib3.exceptions.MaxRetryError: HTTPSConnectionPool(host='api.wandb.ai', port=443): Max retries exceeded with url: /graphql (Caused by ConnectTimeoutError(<urllib3.connection.HTTPSConnection object at 0x00000264EFE0DA50>, 'Connection to api.wandb.ai timed out. (connect timeout=20)'))

During handling of the above exception, another exception occurred:

Traceback (most recent call last):
  File "C:\Users\grego\AppData\Local\Programs\Python\Python311\Lib\site-packages\wandb\sdk\lib\retry.py", line 131, in __call__
    result = self._call_fn(*args, **kwargs)
             ^^^^^^^^^^^^^^^^^^^^^^^^^^^^^^
  File "C:\Users\grego\AppData\Local\Programs\Python\Python311\Lib\site-packages\wandb\sdk\internal\internal_api.py", line 345, in execute
    return self.client.execute(*args, **kwargs)  # type: ignore
           ^^^^^^^^^^^^^^^^^^^^^^^^^^^^^^^^^^^^
  File "C:\Users\grego\AppData\Local\Programs\Python\Python311\Lib\site-packages\wandb\vendor\gql-0.2.0\wandb_gql\client.py", line 52, in execute
    result = self._get_result(document, *args, **kwargs)
             ^^^^^^^^^^^^^^^^^^^^^^^^^^^^^^^^^^^^^^^^^^^
  File "C:\Users\grego\AppData\Local\Programs\Python\Python311\Lib\site-packages\wandb\vendor\gql-0.2.0\wandb_gql\client.py", line 60, in _get_result
    return self.transport.execute(document, *args, **kwargs)
           ^^^^^^^^^^^^^^^^^^^^^^^^^^^^^^^^^^^^^^^^^^^^^^^^^
  File "C:\Users\grego\AppData\Local\Programs\Python\Python311\Lib\site-packages\wandb\sdk\lib\gql_request.py", line 58, in execute
    request = self.session.post(self.url, **post_args)
              ^^^^^^^^^^^^^^^^^^^^^^^^^^^^^^^^^^^^^^^^
  File "C:\Users\grego\AppData\Local\Programs\Python\Python311\Lib\site-packages\requests\sessions.py", line 637, in post
    return self.request("POST", url, data=data, json=json, **kwargs)
           ^^^^^^^^^^^^^^^^^^^^^^^^^^^^^^^^^^^^^^^^^^^^^^^^^^^^^^^^^
  File "C:\Users\grego\AppData\Local\Programs\Python\Python311\Lib\site-packages\requests\sessions.py", line 589, in request
    resp = self.send(prep, **send_kwargs)
           ^^^^^^^^^^^^^^^^^^^^^^^^^^^^^^
  File "C:\Users\grego\AppData\Local\Programs\Python\Python311\Lib\site-packages\requests\sessions.py", line 703, in send
    r = adapter.send(request, **kwargs)
        ^^^^^^^^^^^^^^^^^^^^^^^^^^^^^^^
  File "C:\Users\grego\AppData\Local\Programs\Python\Python311\Lib\site-packages\requests\adapters.py", line 688, in send
    raise ConnectTimeout(e, request=request)
requests.exceptions.ConnectTimeout: HTTPSConnectionPool(host='api.wandb.ai', port=443): Max retries exceeded with url: /graphql (Caused by ConnectTimeoutError(<urllib3.connection.HTTPSConnection object at 0x00000264EFE0DA50>, 'Connection to api.wandb.ai timed out. (connect timeout=20)'))
2024-07-18 15:18:40,297 INFO    Thread-10 (wrapped_target):9420 [retry.py:__call__():172] Retry attempt failed:
Traceback (most recent call last):
  File "C:\Users\grego\AppData\Local\Programs\Python\Python311\Lib\site-packages\urllib3\connection.py", line 196, in _new_conn
    sock = connection.create_connection(
           ^^^^^^^^^^^^^^^^^^^^^^^^^^^^^
  File "C:\Users\grego\AppData\Local\Programs\Python\Python311\Lib\site-packages\urllib3\util\connection.py", line 85, in create_connection
    raise err
  File "C:\Users\grego\AppData\Local\Programs\Python\Python311\Lib\site-packages\urllib3\util\connection.py", line 73, in create_connection
    sock.connect(sa)
TimeoutError: timed out

The above exception was the direct cause of the following exception:

Traceback (most recent call last):
  File "C:\Users\grego\AppData\Local\Programs\Python\Python311\Lib\site-packages\urllib3\connectionpool.py", line 789, in urlopen
    response = self._make_request(
               ^^^^^^^^^^^^^^^^^^^
  File "C:\Users\grego\AppData\Local\Programs\Python\Python311\Lib\site-packages\urllib3\connectionpool.py", line 490, in _make_request
    raise new_e
  File "C:\Users\grego\AppData\Local\Programs\Python\Python311\Lib\site-packages\urllib3\connectionpool.py", line 466, in _make_request
    self._validate_conn(conn)
  File "C:\Users\grego\AppData\Local\Programs\Python\Python311\Lib\site-packages\urllib3\connectionpool.py", line 1095, in _validate_conn
    conn.connect()
  File "C:\Users\grego\AppData\Local\Programs\Python\Python311\Lib\site-packages\urllib3\connection.py", line 615, in connect
    self.sock = sock = self._new_conn()
                       ^^^^^^^^^^^^^^^^
  File "C:\Users\grego\AppData\Local\Programs\Python\Python311\Lib\site-packages\urllib3\connection.py", line 205, in _new_conn
    raise ConnectTimeoutError(
urllib3.exceptions.ConnectTimeoutError: (<urllib3.connection.HTTPSConnection object at 0x00000264EFE0EF10>, 'Connection to api.wandb.ai timed out. (connect timeout=20)')

The above exception was the direct cause of the following exception:

Traceback (most recent call last):
  File "C:\Users\grego\AppData\Local\Programs\Python\Python311\Lib\site-packages\requests\adapters.py", line 667, in send
    resp = conn.urlopen(
           ^^^^^^^^^^^^^
  File "C:\Users\grego\AppData\Local\Programs\Python\Python311\Lib\site-packages\urllib3\connectionpool.py", line 843, in urlopen
    retries = retries.increment(
              ^^^^^^^^^^^^^^^^^^
  File "C:\Users\grego\AppData\Local\Programs\Python\Python311\Lib\site-packages\urllib3\util\retry.py", line 519, in increment
    raise MaxRetryError(_pool, url, reason) from reason  # type: ignore[arg-type]
    ^^^^^^^^^^^^^^^^^^^^^^^^^^^^^^^^^^^^^^^^^^^^^^^^^^^
urllib3.exceptions.MaxRetryError: HTTPSConnectionPool(host='api.wandb.ai', port=443): Max retries exceeded with url: /graphql (Caused by ConnectTimeoutError(<urllib3.connection.HTTPSConnection object at 0x00000264EFE0EF10>, 'Connection to api.wandb.ai timed out. (connect timeout=20)'))

During handling of the above exception, another exception occurred:

Traceback (most recent call last):
  File "C:\Users\grego\AppData\Local\Programs\Python\Python311\Lib\site-packages\wandb\sdk\lib\retry.py", line 131, in __call__
    result = self._call_fn(*args, **kwargs)
             ^^^^^^^^^^^^^^^^^^^^^^^^^^^^^^
  File "C:\Users\grego\AppData\Local\Programs\Python\Python311\Lib\site-packages\wandb\sdk\internal\internal_api.py", line 345, in execute
    return self.client.execute(*args, **kwargs)  # type: ignore
           ^^^^^^^^^^^^^^^^^^^^^^^^^^^^^^^^^^^^
  File "C:\Users\grego\AppData\Local\Programs\Python\Python311\Lib\site-packages\wandb\vendor\gql-0.2.0\wandb_gql\client.py", line 52, in execute
    result = self._get_result(document, *args, **kwargs)
             ^^^^^^^^^^^^^^^^^^^^^^^^^^^^^^^^^^^^^^^^^^^
  File "C:\Users\grego\AppData\Local\Programs\Python\Python311\Lib\site-packages\wandb\vendor\gql-0.2.0\wandb_gql\client.py", line 60, in _get_result
    return self.transport.execute(document, *args, **kwargs)
           ^^^^^^^^^^^^^^^^^^^^^^^^^^^^^^^^^^^^^^^^^^^^^^^^^
  File "C:\Users\grego\AppData\Local\Programs\Python\Python311\Lib\site-packages\wandb\sdk\lib\gql_request.py", line 58, in execute
    request = self.session.post(self.url, **post_args)
              ^^^^^^^^^^^^^^^^^^^^^^^^^^^^^^^^^^^^^^^^
  File "C:\Users\grego\AppData\Local\Programs\Python\Python311\Lib\site-packages\requests\sessions.py", line 637, in post
    return self.request("POST", url, data=data, json=json, **kwargs)
           ^^^^^^^^^^^^^^^^^^^^^^^^^^^^^^^^^^^^^^^^^^^^^^^^^^^^^^^^^
  File "C:\Users\grego\AppData\Local\Programs\Python\Python311\Lib\site-packages\requests\sessions.py", line 589, in request
    resp = self.send(prep, **send_kwargs)
           ^^^^^^^^^^^^^^^^^^^^^^^^^^^^^^
  File "C:\Users\grego\AppData\Local\Programs\Python\Python311\Lib\site-packages\requests\sessions.py", line 703, in send
    r = adapter.send(request, **kwargs)
        ^^^^^^^^^^^^^^^^^^^^^^^^^^^^^^^
  File "C:\Users\grego\AppData\Local\Programs\Python\Python311\Lib\site-packages\requests\adapters.py", line 688, in send
    raise ConnectTimeout(e, request=request)
requests.exceptions.ConnectTimeout: HTTPSConnectionPool(host='api.wandb.ai', port=443): Max retries exceeded with url: /graphql (Caused by ConnectTimeoutError(<urllib3.connection.HTTPSConnection object at 0x00000264EFE0EF10>, 'Connection to api.wandb.ai timed out. (connect timeout=20)'))
2024-07-18 15:19:13,063 ERROR   MainThread:9420 [wandb_init.py:init():779] encountered error: Run initialization has timed out after 90.0 sec. 
Please refer to the documentation for additional information: https://docs.wandb.ai/guides/track/tracking-faq#initstarterror-error-communicating-with-wandb-process-
2024-07-18 15:19:13,063 ERROR   MainThread:9420 [wandb_init.py:init():1191] error in wandb.init()
Traceback (most recent call last):
  File "C:\Users\grego\AppData\Local\Programs\Python\Python311\Lib\site-packages\wandb\sdk\wandb_init.py", line 1181, in init
    return wi.init()
           ^^^^^^^^^
  File "C:\Users\grego\AppData\Local\Programs\Python\Python311\Lib\site-packages\wandb\sdk\wandb_init.py", line 785, in init
    raise error
wandb.errors.CommError: Run initialization has timed out after 90.0 sec. 
Please refer to the documentation for additional information: https://docs.wandb.ai/guides/track/tracking-faq#initstarterror-error-communicating-with-wandb-process-
2024-07-18 15:19:16,089 WARNING MsgRouterThr:9420 [router.py:message_loop():77] message_loop has been closed
