2024-07-18 15:17:42,052 INFO    StreamThr :22548 [internal.py:wandb_internal():85] W&B internal server running at pid: 22548, started at: 2024-07-18 15:17:42.052493
2024-07-18 15:17:42,053 DEBUG   HandlerThread:22548 [handler.py:handle_request():158] handle_request: status
2024-07-18 15:17:42,056 INFO    WriterThread:22548 [datastore.py:open_for_write():87] open: E:\psychic-chainsaw\wandb\run-20240718_151742-rt9bn95e\run-rt9bn95e.wandb
2024-07-18 15:17:42,056 DEBUG   SenderThread:22548 [sender.py:send():379] send: header
2024-07-18 15:17:42,093 DEBUG   SenderThread:22548 [sender.py:send():379] send: run
2024-07-18 15:17:47,158 DEBUG   HandlerThread:22548 [handler.py:handle_request():158] handle_request: keepalive
2024-07-18 15:17:52,207 DEBUG   HandlerThread:22548 [handler.py:handle_request():158] handle_request: keepalive
2024-07-18 15:17:57,245 DEBUG   HandlerThread:22548 [handler.py:handle_request():158] handle_request: keepalive
2024-07-18 15:18:02,314 DEBUG   HandlerThread:22548 [handler.py:handle_request():158] handle_request: keepalive
2024-07-18 15:18:07,367 DEBUG   HandlerThread:22548 [handler.py:handle_request():158] handle_request: keepalive
2024-07-18 15:18:12,430 DEBUG   HandlerThread:22548 [handler.py:handle_request():158] handle_request: keepalive
2024-07-18 15:18:17,501 DEBUG   HandlerThread:22548 [handler.py:handle_request():158] handle_request: keepalive
2024-07-18 15:18:22,557 DEBUG   HandlerThread:22548 [handler.py:handle_request():158] handle_request: keepalive
2024-07-18 15:18:27,613 DEBUG   HandlerThread:22548 [handler.py:handle_request():158] handle_request: keepalive
2024-07-18 15:18:32,668 DEBUG   HandlerThread:22548 [handler.py:handle_request():158] handle_request: keepalive
2024-07-18 15:18:37,721 DEBUG   HandlerThread:22548 [handler.py:handle_request():158] handle_request: keepalive
2024-07-18 15:18:42,764 DEBUG   HandlerThread:22548 [handler.py:handle_request():158] handle_request: keepalive
2024-07-18 15:18:45,351 INFO    SenderThread:22548 [retry.py:__call__():172] Retry attempt failed:
Traceback (most recent call last):
  File "C:\Users\grego\AppData\Local\Programs\Python\Python311\Lib\site-packages\urllib3\connection.py", line 196, in _new_conn
    sock = connection.create_connection(
           ^^^^^^^^^^^^^^^^^^^^^^^^^^^^^
  File "C:\Users\grego\AppData\Local\Programs\Python\Python311\Lib\site-packages\urllib3\util\connection.py", line 85, in create_connection
    raise err
  File "C:\Users\grego\AppData\Local\Programs\Python\Python311\Lib\site-packages\urllib3\util\connection.py", line 73, in create_connection
    sock.connect(sa)
TimeoutError: timed out

The above exception was the direct cause of the following exception:

Traceback (most recent call last):
  File "C:\Users\grego\AppData\Local\Programs\Python\Python311\Lib\site-packages\urllib3\connectionpool.py", line 789, in urlopen
    response = self._make_request(
               ^^^^^^^^^^^^^^^^^^^
  File "C:\Users\grego\AppData\Local\Programs\Python\Python311\Lib\site-packages\urllib3\connectionpool.py", line 490, in _make_request
    raise new_e
  File "C:\Users\grego\AppData\Local\Programs\Python\Python311\Lib\site-packages\urllib3\connectionpool.py", line 466, in _make_request
    self._validate_conn(conn)
  File "C:\Users\grego\AppData\Local\Programs\Python\Python311\Lib\site-packages\urllib3\connectionpool.py", line 1095, in _validate_conn
    conn.connect()
  File "C:\Users\grego\AppData\Local\Programs\Python\Python311\Lib\site-packages\urllib3\connection.py", line 615, in connect
    self.sock = sock = self._new_conn()
                       ^^^^^^^^^^^^^^^^
  File "C:\Users\grego\AppData\Local\Programs\Python\Python311\Lib\site-packages\urllib3\connection.py", line 205, in _new_conn
    raise ConnectTimeoutError(
urllib3.exceptions.ConnectTimeoutError: (<urllib3.connection.HTTPSConnection object at 0x0000019981FAEFD0>, 'Connection to api.wandb.ai timed out. (connect timeout=20)')

The above exception was the direct cause of the following exception:

Traceback (most recent call last):
  File "C:\Users\grego\AppData\Local\Programs\Python\Python311\Lib\site-packages\requests\adapters.py", line 667, in send
    resp = conn.urlopen(
           ^^^^^^^^^^^^^
  File "C:\Users\grego\AppData\Local\Programs\Python\Python311\Lib\site-packages\urllib3\connectionpool.py", line 843, in urlopen
    retries = retries.increment(
              ^^^^^^^^^^^^^^^^^^
  File "C:\Users\grego\AppData\Local\Programs\Python\Python311\Lib\site-packages\urllib3\util\retry.py", line 519, in increment
    raise MaxRetryError(_pool, url, reason) from reason  # type: ignore[arg-type]
    ^^^^^^^^^^^^^^^^^^^^^^^^^^^^^^^^^^^^^^^^^^^^^^^^^^^
urllib3.exceptions.MaxRetryError: HTTPSConnectionPool(host='api.wandb.ai', port=443): Max retries exceeded with url: /graphql (Caused by ConnectTimeoutError(<urllib3.connection.HTTPSConnection object at 0x0000019981FAEFD0>, 'Connection to api.wandb.ai timed out. (connect timeout=20)'))

During handling of the above exception, another exception occurred:

Traceback (most recent call last):
  File "C:\Users\grego\AppData\Local\Programs\Python\Python311\Lib\site-packages\wandb\sdk\lib\retry.py", line 131, in __call__
    result = self._call_fn(*args, **kwargs)
             ^^^^^^^^^^^^^^^^^^^^^^^^^^^^^^
  File "C:\Users\grego\AppData\Local\Programs\Python\Python311\Lib\site-packages\wandb\sdk\internal\internal_api.py", line 345, in execute
    return self.client.execute(*args, **kwargs)  # type: ignore
           ^^^^^^^^^^^^^^^^^^^^^^^^^^^^^^^^^^^^
  File "C:\Users\grego\AppData\Local\Programs\Python\Python311\Lib\site-packages\wandb\vendor\gql-0.2.0\wandb_gql\client.py", line 52, in execute
    result = self._get_result(document, *args, **kwargs)
             ^^^^^^^^^^^^^^^^^^^^^^^^^^^^^^^^^^^^^^^^^^^
  File "C:\Users\grego\AppData\Local\Programs\Python\Python311\Lib\site-packages\wandb\vendor\gql-0.2.0\wandb_gql\client.py", line 60, in _get_result
    return self.transport.execute(document, *args, **kwargs)
           ^^^^^^^^^^^^^^^^^^^^^^^^^^^^^^^^^^^^^^^^^^^^^^^^^
  File "C:\Users\grego\AppData\Local\Programs\Python\Python311\Lib\site-packages\wandb\sdk\lib\gql_request.py", line 58, in execute
    request = self.session.post(self.url, **post_args)
              ^^^^^^^^^^^^^^^^^^^^^^^^^^^^^^^^^^^^^^^^
  File "C:\Users\grego\AppData\Local\Programs\Python\Python311\Lib\site-packages\requests\sessions.py", line 637, in post
    return self.request("POST", url, data=data, json=json, **kwargs)
           ^^^^^^^^^^^^^^^^^^^^^^^^^^^^^^^^^^^^^^^^^^^^^^^^^^^^^^^^^
  File "C:\Users\grego\AppData\Local\Programs\Python\Python311\Lib\site-packages\requests\sessions.py", line 589, in request
    resp = self.send(prep, **send_kwargs)
           ^^^^^^^^^^^^^^^^^^^^^^^^^^^^^^
  File "C:\Users\grego\AppData\Local\Programs\Python\Python311\Lib\site-packages\requests\sessions.py", line 703, in send
    r = adapter.send(request, **kwargs)
        ^^^^^^^^^^^^^^^^^^^^^^^^^^^^^^^
  File "C:\Users\grego\AppData\Local\Programs\Python\Python311\Lib\site-packages\requests\adapters.py", line 688, in send
    raise ConnectTimeout(e, request=request)
requests.exceptions.ConnectTimeout: HTTPSConnectionPool(host='api.wandb.ai', port=443): Max retries exceeded with url: /graphql (Caused by ConnectTimeoutError(<urllib3.connection.HTTPSConnection object at 0x0000019981FAEFD0>, 'Connection to api.wandb.ai timed out. (connect timeout=20)'))
2024-07-18 15:18:47,808 DEBUG   HandlerThread:22548 [handler.py:handle_request():158] handle_request: keepalive
2024-07-18 15:18:52,848 DEBUG   HandlerThread:22548 [handler.py:handle_request():158] handle_request: keepalive
2024-07-18 15:18:57,911 DEBUG   HandlerThread:22548 [handler.py:handle_request():158] handle_request: keepalive
2024-07-18 15:19:02,980 DEBUG   HandlerThread:22548 [handler.py:handle_request():158] handle_request: keepalive
2024-07-18 15:19:08,021 DEBUG   HandlerThread:22548 [handler.py:handle_request():158] handle_request: keepalive
2024-07-18 15:19:13,063 DEBUG   HandlerThread:22548 [handler.py:handle_request():158] handle_request: cancel
2024-07-18 15:19:13,063 DEBUG   HandlerThread:22548 [handler.py:handle_request():158] handle_request: cancel
2024-07-18 15:19:13,063 DEBUG   SenderThread:22548 [sender.py:send():388] Record cancelled: run
2024-07-18 15:19:13,063 DEBUG   HandlerThread:22548 [handler.py:handle_request():158] handle_request: status_report
2024-07-18 15:19:15,076 DEBUG   HandlerThread:22548 [handler.py:handle_request():158] handle_request: shutdown
2024-07-18 15:19:15,076 INFO    HandlerThread:22548 [handler.py:finish():882] shutting down handler
2024-07-18 15:19:15,090 INFO    WriterThread:22548 [datastore.py:close():296] close: E:\psychic-chainsaw\wandb\run-20240718_151742-rt9bn95e\run-rt9bn95e.wandb
2024-07-18 15:19:15,090 INFO    SenderThread:22548 [sender.py:finish():1608] shutting down sender
